<?xml version="1.0" encoding="utf-8"?>
<!-- =================================================================================== -->
<!-- |    This document was autogenerated by xacro from robot.xacro                    | -->
<!-- |    EDITING THIS FILE BY HAND IS NOT RECOMMENDED                                 | -->
<!-- =================================================================================== -->

<robot name="cx300s">
  <material name="black">
    <color rgba="0.0 0.0 0.0 1.0"/>
  </material>
  <material name="blue">
    <color rgba="0.0 0.0 0.8 1.0"/>
  </material>
  <material name="green">
    <color rgba="0.0 0.8 0.0 1.0"/>
  </material>
  <material name="grey">
    <color rgba="0.2 0.2 0.2 1.0"/>
  </material>
  <material name="grey2">
    <color rgba="0.2 0.2 0.2 0.1"/>
  </material>
  <material name="silver">
    <color rgba="0.913725490196 0.913725490196 0.847058823529 1.0"/>
  </material>
  <material name="orange">
    <color rgba="1.0 0.423529411765 0.0392156862745 1.0"/>
  </material>
  <material name="brown">
    <color rgba="0.870588235294 0.811764705882 0.764705882353 1.0"/>
  </material>
  <material name="red">
    <color rgba="0.8 0.0 0.0 1.0"/>
  </material>
  <material name="white">
    <color rgba="1.0 1.0 1.0 1.0"/>
  </material>

 <link name="base">
    <visual>
      <origin rpy="0 0 0" xyz="0 0 0"/>
      <geometry>
        <mesh filename="package://cx300s_meshes/base.stl" scale="0.001 0.001 0.001"/>
      </geometry>
      <material name="interbotix_black"/>
    </visual>
    <collision>
      <origin rpy="0 0 0" xyz="0 0 0"/>
      <geometry>
        <mesh filename="package://cx300s_meshes/base.stl" scale="0.001 0.001 0.001"/>
      </geometry>
    </collision>
    <inertial> 
            <mass value="0.24"/>
            <inertia ixx="0" ixy="0.06" ixz="1" iyy="0" iyz="1" izz="-0.06"/>
        </inertial> 
        <contact> 
            <lateral_friction value="1"/>
        </contact>
  </link>

 <link name="waist">
    <visual>
      <origin rpy="0 0 0" xyz="0 0 0"/>
      <geometry>
        <mesh filename="package://cx300s_meshes/waist.stl" scale="0.001 0.001 0.001"/>
      </geometry>
      <material name="interbotix_black"/>
    </visual>
    <collision>
      <origin rpy="0 0 0" xyz="0 0 0"/>
      <geometry>
        <mesh filename="package://cx300s_meshes/waist.stl" scale="0.001 0.001 0.001"/>
      </geometry>
    </collision>
    <inertial> 
            <mass value="0.23"/>
            <inertia ixx="0" ixy="1" ixz="-0.06" iyy="0" iyz="0" izz="1"/>
        </inertial> 
        <contact> 
            <lateral_friction value="1"/>
        </contact>
  </link>

  <joint name="base_waist" type="revolute">
    <origin rpy="0 0 3.14" xyz="0 0 0.054"/>
    <parent link="base"/>
    <child link="waist"/>
    <axis xyz="0 0 1"/>
    <dynamics damping="0" friction="0"/>
    <limit effort="100" lower="-3.14" upper="3.14" velocity="20"/>
  </joint>

 <link name="shoulder">
    <visual>
      <origin rpy="0 0 0" xyz="0 0 0"/>
      <geometry>
        <mesh filename="package://cx300s_meshes/shoulder.stl" scale="0.001 0.001 0.001"/>
      </geometry>
      <material name="interbotix_black"/>
    </visual>
    <collision>
      <origin rpy="0 0 0" xyz="0 0 0"/>
      <geometry>
        <mesh filename="package://cx300s_meshes/shoulder.stl" scale="0.001 0.001 0.001"/>
      </geometry>
    </collision>
    <inertial> 
            <mass value="0.31"/>
            <inertia ixx="0" ixy="1" ixz="0.04" iyy="-0.04" iyz="1" izz="0"/>
        </inertial> 
        <contact> 
            <lateral_friction value="1"/>
        </contact>
  </link>

  <joint name="waist_shoulder" type="revolute">
    <origin rpy="0 0 0" xyz="0 0 0.07"/>
    <parent link="waist"/>
    <child link="shoulder"/>
    <axis xyz="0 -1 0"/>
    <dynamics damping="0" friction="0"/>
    <limit effort="100" lower="-3.14" upper="3.14" velocity="20"/>
  </joint>


 <link name="forearm">
    <visual>
      <origin rpy="0 0 0" xyz="0 0 0"/>
      <geometry>
        <mesh filename="package://cx300s_meshes/forearm.stl" scale="0.001 0.001 0.001"/>
      </geometry>
      <material name="interbotix_black"/>
    </visual>
    <collision>
      <origin rpy="0 0 0" xyz="0 0 0"/>
      <geometry>
        <mesh filename="package://cx300s_meshes/forearm.stl" scale="0.001 0.001 0.001"/>
      </geometry>
    </collision>
    <inertial> 
            <mass value="0.1"/>
            <inertia ixx="0" ixy="1" ixz="0" iyy="0" iyz="0" izz="1"/>
        </inertial> 
        <contact> 
            <lateral_friction value="1"/>
        </contact>
  </link>

  <joint name="arm_forearm" type="revolute">
    <origin rpy="0 -1.57 0" xyz="-0.06 0 0.3"/>
    <parent link="shoulder"/>
    <child link="forearm"/>
    <axis xyz="0 -1 0"/>
    <dynamics damping="0" friction="0"/>
    <limit effort="100" lower="-3.14" upper="3.14" velocity="20"/>
  </joint>

 <link name="wrist">
    <visual>
      <origin rpy="0 0 0" xyz="0 0 0"/>
      <geometry>
        <mesh filename="package://cx300s_meshes/wrist.stl" scale="0.001 0.001 0.001"/>
      </geometry>
      <material name="interbotix_black"/>
    </visual>
    <collision>
      <origin rpy="0 0 0" xyz="0 0 0"/>
      <geometry>
        <mesh filename="package://cx300s_meshes/wrist.stl" scale="0.001 0.001 0.001"/>
      </geometry>
    </collision>
    <inertial> 
            <mass value="0.11"/>
            <inertia ixx="0" ixy="1" ixz="0" iyy="0" iyz="0" izz="1"/>
        </inertial> 
        <contact> 
            <lateral_friction value="1"/>
        </contact>
  </link>

  <joint name="forearm_wrist" type="revolute">
    <origin rpy="0 0 0" xyz="0 0 0.25"/>
    <parent link="forearm"/>
    <child link="wrist"/>
    <axis xyz="0 0 1"/>
    <dynamics damping="0" friction="0"/>
    <limit effort="100" lower="-3.14" upper="3.14" velocity="20"/>
  </joint>

 <link name="wrist2">
    <visual>
      <origin rpy="0 0 0" xyz="0 0 0"/>
      <geometry>
        <mesh filename="package://cx300s_meshes/wrist2.stl" scale="0.001 0.001 0.001"/>
      </geometry>
      <material name="interbotix_black"/>
    </visual>
    <collision>
      <origin rpy="0 0 0" xyz="0 0 0"/>
      <geometry>
        <mesh filename="package://cx300s_meshes/wrist2.stl" scale="0.001 0.001 0.001"/>
      </geometry>
    </collision>
    <inertial> 
            <mass value="0.1"/>
            <inertia ixx="0.02" ixy="0.98" ixz="0.18" iyy="-0.18" iyz="0.98" izz="0.02"/>
        </inertial> 
        <contact> 
            <lateral_friction value="1"/>
        </contact>
  </link>

  <joint name="wrist_wrist2" type="revolute">
    <origin rpy="0 0 0" xyz="0 0.002 0.054"/>
    <parent link="wrist"/>
    <child link="wrist2"/>
    <axis xyz="0 -1 0"/>
    <dynamics damping="0" friction="0"/>
    <limit effort="100" lower="-3.14" upper="3.14" velocity="20"/>
  </joint>

<link name="wrist3">
    <visual>
      <origin rpy="0 0 0" xyz="0 0 0"/>
      <geometry>
        <mesh filename="package://cx300s_meshes/ee_wrist.stl" scale="0.001 0.001 0.001"/>
      </geometry>
      <material name="interbotix_black"/>
    </visual>
    <collision>
      <origin rpy="0 0 0" xyz="0 0 0"/>
      <geometry>
        <mesh filename="package://cx300s_meshes/ee_wrist.stl" scale="0.001 0.001 0.001"/>
      </geometry>
    </collision>
    <inertial> 
            <mass value="0.11"/>
            <inertia ixx="0" ixy="1" ixz="0" iyy="0" iyz="0" izz="1"/>
        </inertial> 
        <contact> 
            <lateral_friction value="1"/>
        </contact>
  </link>

  <joint name="wrist2_wrist3" type="revolute">
    <origin rpy="0 0 0" xyz="0 0 0.07"/>
    <parent link="wrist2"/>
    <child link="wrist3"/>
    <axis xyz="0 0 1"/>
    <dynamics damping="0" friction="0"/>
    <limit effort="100" lower="-3.14" upper="3.14" velocity="20"/>
  </joint>

  <link name="ee">
    <visual>
      <origin rpy="0 0 0" xyz="0 0 0"/>
      <geometry>
        <mesh filename="package://cx300s_meshes/ee.stl" scale="0.001 0.001 0.001"/>
      </geometry>
      <material name="interbotix_black"/>
    </visual>
    <collision>
      <origin rpy="0 0 0" xyz="0 0 0"/>
      <geometry>
        <mesh filename="package://cx300s_meshes/ee.stl" scale="0.001 0.001 0.001"/>
      </geometry>
    </collision>
    <inertial> 
            <mass value="0.11"/>
            <inertia ixx="0" ixy="1" ixz="0" iyy="0" iyz="0" izz="1"/>
        </inertial> 
        <contact> 
            <lateral_friction value="1"/>
        </contact>
  </link>

  <joint name="wrist3_ee" type="fixed">
    <origin rpy="0 0 0" xyz="0 0 0.047"/>
    <parent link="wrist3"/>
    <child link="ee"/>
  </joint>

    <link name="end_effector">
        <visual> 
            <geometry> 
                <box size="0.05 0.05 0.05"/>
                <origin rpy="0 0 0" xyz="0 0 0"/>
            </geometry>
            <material name="grey2"/>
        </visual>
    </link> 

    <joint name="fart" type="fixed">
        <origin rpy="0 0 0" xyz="0 0 0.085"/>
        <parent link="ee"/>
        <child link="end_effector"/>
    </joint>


</robot>

